Traceback (most recent call last):
  File "/home/brenden/.virtualenvs/phishing/lib/python3.8/site-packages/urllib3/connectionpool.py", line 703, in urlopen
    httplib_response = self._make_request(
  File "/home/brenden/.virtualenvs/phishing/lib/python3.8/site-packages/urllib3/connectionpool.py", line 386, in _make_request
    self._validate_conn(conn)
  File "/home/brenden/.virtualenvs/phishing/lib/python3.8/site-packages/urllib3/connectionpool.py", line 1040, in _validate_conn
    conn.connect()
  File "/home/brenden/.virtualenvs/phishing/lib/python3.8/site-packages/urllib3/connection.py", line 414, in connect
    self.sock = ssl_wrap_socket(
  File "/home/brenden/.virtualenvs/phishing/lib/python3.8/site-packages/urllib3/util/ssl_.py", line 449, in ssl_wrap_socket
    ssl_sock = _ssl_wrap_socket_impl(
  File "/home/brenden/.virtualenvs/phishing/lib/python3.8/site-packages/urllib3/util/ssl_.py", line 493, in _ssl_wrap_socket_impl
    return ssl_context.wrap_socket(sock, server_hostname=server_hostname)
  File "/usr/lib/python3.8/ssl.py", line 500, in wrap_socket
    return self.sslsocket_class._create(
  File "/usr/lib/python3.8/ssl.py", line 1040, in _create
    self.do_handshake()
  File "/usr/lib/python3.8/ssl.py", line 1309, in do_handshake
    self._sslobj.do_handshake()
ssl.SSLCertVerificationError: [SSL: CERTIFICATE_VERIFY_FAILED] certificate verify failed: unable to get local issuer certificate (_ssl.c:1131)

During handling of the above exception, another exception occurred:

Traceback (most recent call last):
  File "/home/brenden/.virtualenvs/phishing/lib/python3.8/site-packages/requests/adapters.py", line 440, in send
    resp = conn.urlopen(
  File "/home/brenden/.virtualenvs/phishing/lib/python3.8/site-packages/urllib3/connectionpool.py", line 785, in urlopen
    retries = retries.increment(
  File "/home/brenden/.virtualenvs/phishing/lib/python3.8/site-packages/urllib3/util/retry.py", line 592, in increment
    raise MaxRetryError(_pool, url, error or ResponseError(cause))
urllib3.exceptions.MaxRetryError: HTTPSConnectionPool(host='business-page-appeal-125236-1.web.app', port=443): Max retries exceeded with url: /appeal.html (Caused by SSLError(SSLCertVerificationError(1, '[SSL: CERTIFICATE_VERIFY_FAILED] certificate verify failed: unable to get local issuer certificate (_ssl.c:1131)')))

During handling of the above exception, another exception occurred:

Traceback (most recent call last):
  File "code.py", line 303, in <module>
    main()
  File "code.py", line 298, in main
    run(site)
  File "code.py", line 278, in run
    ret_val = phishing_identification_algo(webpage)
  File "code.py", line 226, in phishing_identification_algo
    hyperlinks_set, num_hyperlinks = calculate_hyperlink(webpage)    
  File "code.py", line 149, in calculate_hyperlink
    resp=requests.get(url)
  File "/home/brenden/.virtualenvs/phishing/lib/python3.8/site-packages/requests/api.py", line 75, in get
    return request('get', url, params=params, **kwargs)
  File "/home/brenden/.virtualenvs/phishing/lib/python3.8/site-packages/requests/api.py", line 61, in request
    return session.request(method=method, url=url, **kwargs)
  File "/home/brenden/.virtualenvs/phishing/lib/python3.8/site-packages/requests/sessions.py", line 529, in request
    resp = self.send(prep, **send_kwargs)
  File "/home/brenden/.virtualenvs/phishing/lib/python3.8/site-packages/requests/sessions.py", line 645, in send
    r = adapter.send(request, **kwargs)
  File "/home/brenden/.virtualenvs/phishing/lib/python3.8/site-packages/requests/adapters.py", line 517, in send
    raise SSLError(e, request=request)
requests.exceptions.SSLError: HTTPSConnectionPool(host='business-page-appeal-125236-1.web.app', port=443): Max retries exceeded with url: /appeal.html (Caused by SSLError(SSLCertVerificationError(1, '[SSL: CERTIFICATE_VERIFY_FAILED] certificate verify failed: unable to get local issuer certificate (_ssl.c:1131)')))

